ERROR:__main__:Uncaught exception
Traceback (most recent call last):
  File "__main__.py", line 27, in <module>
    app = MainWindow(db_filename=os.path.join(tmp_folder, 'GUIstate_GraphMain'), backup_filename=os.path.join(tmp_folder, 'sampler.txt'), appdata_dir=tmp_folder)
  File "/home/neurorobotic_student/panda-robot-control/panda_ws/src/nils_master_pkg/src/gripper/main_GUI.py", line 29, in __init__
    self.standFrame = ControlFrame(self.mainframe, self.stand)
  File "/home/neurorobotic_student/panda-robot-control/panda_ws/src/nils_master_pkg/src/gripper/Stand_GUI.py", line 33, in __init__
    self.initUI()
  File "/home/neurorobotic_student/panda-robot-control/panda_ws/src/nils_master_pkg/src/gripper/Stand_GUI.py", line 317, in initUI
    self.img_btn_up   = PhotoImage(file = os.path.join(base_folder, 'res/btn_up.png'))
  File "/usr/lib/python3.8/tkinter/__init__.py", line 4064, in __init__
    Image.__init__(self, 'photo', name, cnf, master, **kw)
  File "/usr/lib/python3.8/tkinter/__init__.py", line 4009, in __init__
    self.tk.call(('image', 'create', imgtype, name,) + options)
_tkinter.TclError: couldn't open "/home/neurorobotic_student/panda-robot-control/panda_ws/src/nils_master_pkg/src/gripper/res/btn_up.png": no such file or directory
ERROR:__main__:Uncaught exception
Traceback (most recent call last):
  File "__main__.py", line 27, in <module>
    app = MainWindow(db_filename=os.path.join(tmp_folder, 'GUIstate_GraphMain'), backup_filename=os.path.join(tmp_folder, 'sampler.txt'), appdata_dir=tmp_folder)
  File "/home/neurorobotic_student/panda-robot-control/panda_ws/src/nils_master_pkg/src/gripper/main_GUI.py", line 29, in __init__
    self.standFrame = ControlFrame(self.mainframe, self.stand)
  File "/home/neurorobotic_student/panda-robot-control/panda_ws/src/nils_master_pkg/src/gripper/Stand_GUI.py", line 33, in __init__
    self.initUI()
  File "/home/neurorobotic_student/panda-robot-control/panda_ws/src/nils_master_pkg/src/gripper/Stand_GUI.py", line 322, in initUI
    self.btn_ctrl_up = Button(ctrl_speed_frame, image=self.img_btn_up, command=self.ctrl_up_clicked)
AttributeError: 'ControlFrame' object has no attribute 'img_btn_up'
ERROR:__main__:Uncaught exception
Traceback (most recent call last):
  File "__main__.py", line 27, in <module>
    app = MainWindow(db_filename=os.path.join(tmp_folder, 'GUIstate_GraphMain'), backup_filename=os.path.join(tmp_folder, 'sampler.txt'), appdata_dir=tmp_folder)
  File "/home/neurorobotic_student/panda-robot-control/panda_ws/src/nils_master_pkg/src/gripper/main_GUI.py", line 40, in __init__
    self.calibFrame = CalibratorFrame(self.graphCalibFrame, self.graphFrame, self.sensorFrame, self.standFrame)
  File "/usr/lib/python3.8/tkinter/__init__.py", line 2354, in __getattr__
    return getattr(self.tk, attr)
AttributeError: '_tkinter.tkapp' object has no attribute 'standFrame'
ERROR:__main__:Uncaught exception
Traceback (most recent call last):
  File "__main__.py", line 27, in <module>
    app = MainWindow(db_filename=os.path.join(tmp_folder, 'GUIstate_GraphMain'), backup_filename=os.path.join(tmp_folder, 'sampler.txt'), appdata_dir=tmp_folder)
  File "/home/neurorobotic_student/panda-robot-control/panda_ws/src/nils_master_pkg/src/gripper/main_GUI.py", line 20, in __init__
    self.title(self.MAIN_TITLE)
  File "/usr/lib/python3.8/tkinter/__init__.py", line 2354, in __getattr__
    return getattr(self.tk, attr)
AttributeError: '_tkinter.tkapp' object has no attribute 'MAIN_TITLE'
